Workbook

Sheet MAIO26
B1: Data: 04/05/2026
A2: SABORES | B2: Estoque Inicial | C2: Furou | D2: Fez | E2: Quantidade de Geladinhos | F2: Voltaram | G2: Vendidos | H2: Estoque Final | I2: R$
A3: Abacate | B3: =ABRIL26!H490 -> 35 | E3: 6 | F3: 6 | G3: =E3-F3 -> 0 | H3: =B3-C3+D3-G3 -> 35 | I3: =G3*6 -> 0
A4: Abacaxi | B4: =ABRIL26!H491 -> 28 | E4: 3 | F4: 3 | G4: =E4-F4 -> 0 | H4: =B4-C4+D4-G4 -> 28 | I4: =G4*6 -> 0
A5: Açaí | B5: =ABRIL26!H492 -> 17 | E5: 5 | F5: 4 | G5: =E5-F5 -> 1 | H5: =B5-C5+D5-G5 -> 16 | I5: =G5*6 -> 6
A6: Amendoim | B6: =ABRIL26!H493 -> 32 | E6: 6 | F6: 5 | G6: =E6-F6 -> 1 | H6: =B6-C6+D6-G6 -> 31 | I6: =G6*6 -> 6
A7: Brigadeiro | B7: =ABRIL26!H494 -> 24 | E7: 4 | F7: 3 | G7: =E7-F7 -> 1 | H7: =B7-C7+D7-G7 -> 23 | I7: =G7*6 -> 6
A8: Buriti | B8: =ABRIL26!H495 -> 32 | E8: 6 | F8: 2 | G8: =E8-F8 -> 4 | H8: =B8-C8+D8-G8 -> 28 | I8: =G8*6 -> 24
A9: Coco | B9: =ABRIL26!H496 -> 15 | D9: 30 | E9: 5 | F9: 4 | G9: =E9-F9 -> 1 | H9: =B9-C9+D9-G9 -> 44 | I9: =G9*6 -> 6
A10: Coco Queimado | B10: =ABRIL26!H497 -> 15 | E10: 4 | F10: 3 | G10: =E10-F10 -> 1 | H10: =B10-C10+D10-G10 -> 14 | I10: =G10*6 -> 6
A11: Cupuaçu | B11: =ABRIL26!H498 -> 19 | E11: 5 | F11: 4 | G11: =E11-F11 -> 1 | H11: =B11-C11+D11-G11 -> 18 | I11: =G11*6 -> 6
A12: Maracujá | B12: =ABRIL26!H499 -> 22 | E12: 5 | F12: 5 | G12: =E12-F12 -> 0 | H12: =B12-C12+D12-G12 -> 22 | I12: =G12*6 -> 0
A13: Maracujá com nutella | B13: =ABRIL26!H500 -> 35 | E13: 5 | F13: 5 | G13: =E13-F13 -> 0 | H13: =B13-C13+D13-G13 -> 35 | I13: =G13*6 -> 0
A14: Milho verde | B14: =ABRIL26!H501 -> 8 | E14: 2 | F14: 1 | G14: =E14-F14 -> 1 | H14: =B14-C14+D14-G14 -> 7 | I14: =G14*6 -> 6
A15: Morango | B15: =ABRIL26!H502 -> 34 | C15: 1 | E15: 5 | F15: 4 | G15: =E15-F15 -> 1 | H15: =B15-C15+D15-G15 -> 32 | I15: =G15*6 -> 6
A16: Morango com Nutella | B16: =ABRIL26!H503 -> 32 | E16: 6 | F16: 5 | G16: =E16-F16 -> 1 | H16: =B16-C16+D16-G16 -> 31 | I16: =G16*6 -> 6
A17: Mousse de limão | B17: =ABRIL26!H504 -> 24 | E17: 3 | F17: 3 | G17: =E17-F17 -> 0 | H17: =B17-C17+D17-G17 -> 24 | I17: =G17*6 -> 0
A18: Ninho com Nutella | B18: =ABRIL26!H505 -> 25 | E18: 8 | F18: 2 | G18: =E18-F18 -> 6 | H18: =B18-C18+D18-G18 -> 19 | I18: =G18*6 -> 36
A19: Ninho com Morango | B19: =ABRIL26!H506 -> 17 | E19: 4 | F19: 2 | G19: =E19-F19 -> 2 | H19: =B19-C19+D19-G19 -> 15 | I19: =G19*6 -> 12
A20: Oreo | B20: =ABRIL26!H507 -> 17 | E20: 3 | F20: 2 | G20: =E20-F20 -> 1 | H20: =B20-C20+D20-G20 -> 16 | I20: =G20*6 -> 6
A21: Prestígio | B21: =ABRIL26!H508 -> 20 | E21: 8 | F21: 7 | G21: =E21-F21 -> 1 | H21: =B21-C21+D21-G21 -> 19 | I21: =G21*6 -> 6
A22: Pudim | B22: =ABRIL26!H509 -> 158 | E22: 25 | F22: 13 | G22: =E22-F22 -> 12 | H22: =B22-C22+D22-G22 -> 146 | I22: =G22*6 -> 72
A23: Uva | B23: =ABRIL26!H510 -> 6 | E23: 2 | F23: 2 | G23: =E23-F23 -> 0 | H23: =B23-C23+D23-G23 -> 6 | I23: =G23*6 -> 0
A24: Zero lactose coco | B24: =ABRIL26!H511 -> 12 | E24: 2 | F24: 0 | G24: =E24-F24 -> 2 | H24: =B24-C24+D24-G24 -> 10 | I24: =G24*6 -> 12
A25: Zero lactose morango | B25: =ABRIL26!H512 -> 16 | E25: 2 | F25: 2 | G25: =E25-F25 -> 0 | H25: =B25-C25+D25-G25 -> 16 | I25: =G25*6 -> 0
A26: TOTAL | B26: =SUM(B3:B25) -> 643 | C26: =SUM(C3:C25) -> 1 | D26: =SUM(D3:D25) -> 30 | E26: =SUM(E3:E25) -> 124 | F26: =SUM(F3:F25) -> 87 | G26: =SUM(G3:G25) -> 37 | H26: =SUM(H3:H25) -> 635 | I26: =SUM(I3:I25) -> 222
F27: Saldo
B29: Data: 05/05/2026
A30: SABORES | B30: Estoque Inicial | C30: Furou | D30: Fez | E30: Quantidade de Geladinhos | F30: Voltaram | G30: Vendidos | H30: Estoque Final | I30: R$
A31: Abacate | B31: =H3 -> 35 | E31: 6 | F31: 5 | G31: =E31-F31 -> 1 | H31: =B31-C31+D31-G31 -> 34 | I31: =G31*6 -> 6
A32: Abacaxi | B32: =H4 -> 28 | E32: 3 | F32: 3 | G32: =E32-F32 -> 0 | H32: =B32-C32+D32-G32 -> 28 | I32: =G32*6 -> 0
A33: Açaí | B33: =H5 -> 16 | E33: 5 | F33: 3 | G33: =E33-F33 -> 2 | H33: =B33-C33+D33-G33 -> 14 | I33: =G33*6 -> 12
A34: Amendoim | B34: =H6 -> 31 | E34: 6 | F34: 3 | G34: =E34-F34 -> 3 | H34: =B34-C34+D34-G34 -> 28 | I34: =G34*6 -> 18
A35: Brigadeiro | B35: =H7 -> 23 | E35: 4 | F35: 1 | G35: =E35-F35 -> 3 | H35: =B35-C35+D35-G35 -> 20 | I35: =G35*6 -> 18
A36: Buriti | B36: =H8 -> 28 | E36: 5 | F36: 4 | G36: =E36-F36 -> 1 | H36: =B36-C36+D36-G36 -> 27 | I36: =G36*6 -> 6
A37: Coco | B37: =H9 -> 44 | E37: 5 | F37: 4 | G37: =E37-F37 -> 1 | H37: =B37-C37+D37-G37 -> 43 | I37: =G37*6 -> 6
A38: Coco Queimado | B38: =H10 -> 14 | E38: 4 | F38: 2 | G38: =E38-F38 -> 2 | H38: =B38-C38+D38-G38 -> 12 | I38: =G38*6 -> 12
A39: Cupuaçu | B39: =H11 -> 18 | E39: 5 | F39: 4 | G39: =E39-F39 -> 1 | H39: =B39-C39+D39-G39 -> 17 | I39: =G39*6 -> 6
A40: Maracujá | B40: =H12 -> 22 | E40: 5 | F40: 3 | G40: =E40-F40 -> 2 | H40: =B40-C40+D40-G40 -> 20 | I40: =G40*6 -> 12
A41: Maracujá com nutella | B41: =H13 -> 35 | E41: 5 | F41: 3 | G41: =E41-F41 -> 2 | H41: =B41-C41+D41-G41 -> 33 | I41: =G41*6 -> 12
...

Sheet ABRIL26
B1: Data: 01/04/2026
A2: SABORES | B2: Estoque Inicial | C2: Furou | D2: Fez | E2: Quantidade de Geladinhos | F2: Voltaram | G2: Vendidos | H2: Estoque Final | I2: R$
A3: Abacate | B3: =MARÇO26!H576 -> 36 | C3: 1 | E3: 6 | F3: 0 | G3: =E3-F3 -> 6 | H3: =B3-C3+D3-G3 -> 29 | I3: =G3*6 -> 36
A4: Abacaxi | B4: =MARÇO26!H577 -> 27 | C4: 2 | E4: 4 | F4: 1 | G4: =E4-F4 -> 3 | H4: =B4-C4+D4-G4 -> 22 | I4: =G4*6 -> 18
A5: Açaí | B5: =MARÇO26!H578 -> 26 | E5: 6 | F5: 2 | G5: =E5-F5 -> 4 | H5: =B5-C5+D5-G5 -> 22 | I5: =G5*6 -> 24
A6: Amendoim | B6: =MARÇO26!H579 -> 33 | C6: 1 | E6: 8 | F6: 2 | G6: =E6-F6 -> 6 | H6: =B6-C6+D6-G6 -> 26 | I6: =G6*6 -> 36
A7: Brigadeiro | B7: =MARÇO26!H580 -> 23 | C7: 1 | E7: 4 | F7: 0 | G7: =E7-F7 -> 4 | H7: =B7-C7+D7-G7 -> 18 | I7: =G7*6 -> 24
A8: Buriti | B8: =MARÇO26!H581 -> 13 | E8: 8 | F8: 2 | G8: =E8-F8 -> 6 | H8: =B8-C8+D8-G8 -> 7 | I8: =G8*6 -> 36
A9: Coco | B9: =MARÇO26!H582 -> 18 | E9: 4 | F9: 2 | G9: =E9-F9 -> 2 | H9: =B9-C9+D9-G9 -> 16 | I9: =G9*6 -> 12
A10: Coco Queimado | B10: =MARÇO26!H583 -> 10 | E10: 4 | F10: 3 | G10: =E10-F10 -> 1 | H10: =B10-C10+D10-G10 -> 9 | I10: =G10*6 -> 6
A11: Cupuaçu | B11: =MARÇO26!H584 -> 27 | E11: 6 | F11: 2 | G11: =E11-F11 -> 4 | H11: =B11-C11+D11-G11 -> 23 | I11: =G11*6 -> 24
A12: Maracujá | B12: =MARÇO26!H585 -> 28 | E12: 6 | F12: 6 | G12: =E12-F12 -> 0 | H12: =B12-C12+D12-G12 -> 28 | I12: =G12*6 -> 0
A13: Maracujá com nutella | B13: =MARÇO26!H586 -> 13 | E13: 8 | F13: 4 | G13: =E13-F13 -> 4 | H13: =B13-C13+D13-G13 -> 9 | I13: =G13*6 -> 24
A14: Milho verde | B14: =MARÇO26!H587 -> 5 | E14: 3 | F14: 0 | G14: =E14-F14 -> 3 | H14: =B14-C14+D14-G14 -> 2 | I14: =G14*6 -> 18
A15: Morango | B15: =MARÇO26!H588 -> 7 | D15: 24 | E15: 2 | F15: 0 | G15: =E15-F15 -> 2 | H15: =B15-C15+D15-G15 -> 29 | I15: =G15*6 -> 12
A16: Morango com Nutella | B16: =MARÇO26!H589 -> 36 | C16: 1 | E16: 12 | F16: 1 | G16: =E16-F16 -> 11 | H16: =B16-C16+D16-G16 -> 24 | I16: =G16*6 -> 66
A17: Mousse de limão | B17: =MARÇO26!H590 -> 16 | E17: 4 | F17: 2 | G17: =E17-F17 -> 2 | H17: =B17-C17+D17-G17 -> 14 | I17: =G17*6 -> 12
A18: Ninho com Nutella | B18: =MARÇO26!H591 -> 33 | C18: 1 | E18: 18 | F18: 3 | G18: =E18-F18 -> 15 | H18: =B18-C18+D18-G18 -> 17 | I18: =G18*6 -> 90
A19: Ninho com Morango | B19: =MARÇO26!H592 -> 15 | C19: 1 | E19: 6 | F19: 5 | G19: =E19-F19 -> 1 | H19: =B19-C19+D19-G19 -> 13 | I19: =G19*6 -> 6
A20: Oreo | B20: =MARÇO26!H593 -> 17 | E20: 5 | F20: 1 | G20: =E20-F20 -> 4 | H20: =B20-C20+D20-G20 -> 13 | I20: =G20*6 -> 24
A21: Prestígio | B21: =MARÇO26!H594 -> 44 | C21: 4 | E21: 8 | F21: 4 | G21: =E21-F21 -> 4 | H21: =B21-C21+D21-G21 -> 36 | I21: =G21*6 -> 24
A22: Pudim | B22: =MARÇO26!H595 -> 48 | C22: 3 | D22: 34 | E22: 52 | F22: 11 | G22: =E22-F22 -> 41 | H22: =B22-C22+D22-G22 -> 38 | I22: =G22*6 -> 246
A23: Uva | B23: =MARÇO26!H596 -> 14 | C23: 1 | E23: 3 | F23: 2 | G23: =E23-F23 -> 1 | H23: =B23-C23+D23-G23 -> 12 | I23: =G23*6 -> 6
A24: Zero lactose coco | B24: =MARÇO26!H597 -> 20 | E24: 5 | F24: 3 | G24: =E24-F24 -> 2 | H24: =B24-C24+D24-G24 -> 18 | I24: =G24*6 -> 12
A25: Zero lactose morango | B25: =MARÇO26!H598 -> 19 | E25: 3 | F25: 3 | G25: =E25-F25 -> 0 | H25: =B25-C25+D25-G25 -> 19 | I25: =G25*6 -> 0
A26: TOTAL | B26: =SUM(B3:B25) -> 528 | E26: =SUM(E2:E25) -> 185 | F26: =SUM(F2:F25) -> 59 | G26: =SUM(G2:G25) -> 126 | H26: =SUM(H3:H25) -> 444 | I26: =SUM(I2:I25) -> 756
F27: Saldo
B29: Data: 06/04/2026
A30: SABORES | B30: Estoque Inicial | C30: Furou | D30: Fez | E30: Quantidade de Geladinhos | F30: Voltaram | G30: Vendidos | H30: Estoque Final | I30: R$
A31: Abacate | B31: =H3 -> 29 | E31: 6 | F31: 0 | G31: =E31-F31 -> 6 | H31: =B31-C31+D31-G31 -> 23 | I31: =G31*6 -> 36
A32: Abacaxi | B32: =H4 -> 22 | E32: 3 | F32: 2 | G32: =E32-F32 -> 1 | H32: =B32-C32+D32-G32 -> 21 | I32: =G32*6 -> 6
A33: Açaí | B33: =H5 -> 22 | E33: 5 | F33: 4 | G33: =E33-F33 -> 1 | H33: =B33-C33+D33-G33 -> 21 | I33: =G33*6 -> 6
A34: Amendoim | B34: =H6 -> 26 | E34: 6 | F34: 5 | G34: =E34-F34 -> 1 | H34: =B34-C34+D34-G34 -> 25 | I34: =G34*6 -> 6
A35: Brigadeiro | B35: =H7 -> 18 | E35: 4 | F35: 0 | G35: =E35-F35 -> 4 | H35: =B35-C35+D35-G35 -> 14 | I35: =G35*6 -> 24
A36: Buriti | B36: =H8 -> 7 | E36: 5 | F36: 4 | G36: =E36-F36 -> 1 | H36: =B36-C36+D36-G36 -> 6 | I36: =G36*6 -> 6
A37: Coco | B37: =H9 -> 16 | E37: 4 | F37: 3 | G37: =E37-F37 -> 1 | H37: =B37-C37+D37-G37 -> 15 | I37: =G37*6 -> 6
A38: Coco Queimado | B38: =H10 -> 9 | E38: 3 | F38: 2 | G38: =E38-F38 -> 1 | H38: =B38-C38+D38-G38 -> 8 | I38: =G38*6 -> 6
A39: Cupuaçu | B39: =H11 -> 23 | E39: 5 | F39: 2 | G39: =E39-F39 -> 3 | H39: =B39-C39+D39-G39 -> 20 | I39: =G39*6 -> 18
A40: Maracujá | B40: =H12 -> 28 | E40: 5 | F40: 4 | G40: =E40-F40 -> 1 | H40: =B40-C40+D40-G40 -> 27 | I40: =G40*6 -> 6
A41: Maracujá com nutella | B41: =H13 -> 9 | E41: 5 | F41: 4 | G41: =E41-F41 -> 1 | H41: =B41-C41+D41-G41 -> 8 | I41: =G41*6 -> 6
...

Sheet MARÇO26
B1: Data: 02/03/2026
A2: SABORES | B2: Estoque Inicial | C2: Furou | D2: Fez | E2: Quantidade de Geladinhos | F2: Voltaram | G2: Vendidos | H2: Estoque Final | I2: R$
A3: Abacate | B3: =FEVEREIRO26!H448 -> 19 | E3: 6 | F3: 6 | G3: =E3-F3 -> 0 | H3: =B3-C3+D3-G3 -> 19 | I3: =G3*6 -> 0
A4: Abacaxi | B4: =FEVEREIRO26!H449 -> 41 | E4: 6 | F4: 6 | G4: =E4-F4 -> 0 | H4: =B4-C4+D4-G4 -> 41 | I4: =G4*6 -> 0
A5: Açaí | B5: =FEVEREIRO26!H450 -> 40 | E5: 6 | F5: 6 | G5: =E5-F5 -> 0 | H5: =B5-C5+D5-G5 -> 40 | I5: =G5*6 -> 0
A6: Amendoim | B6: =FEVEREIRO26!H451 -> 31 | C6: 1 | E6: 6 | F6: 5 | G6: =E6-F6 -> 1 | H6: =B6-C6+D6-G6 -> 29 | I6: =G6*6 -> 6
A7: Brigadeiro | B7: =FEVEREIRO26!H452 -> 27 | E7: 4 | F7: 3 | G7: =E7-F7 -> 1 | H7: =B7-C7+D7-G7 -> 26 | I7: =G7*6 -> 6
A8: Buriti | B8: =FEVEREIRO26!H453 -> 14 | E8: 6 | F8: 5 | G8: =E8-F8 -> 1 | H8: =B8-C8+D8-G8 -> 13 | I8: =G8*6 -> 6
A9: Coco | B9: =FEVEREIRO26!H454 -> 25 | E9: 4 | F9: 4 | G9: =E9-F9 -> 0 | H9: =B9-C9+D9-G9 -> 25 | I9: =G9*6 -> 0
A10: Coco Queimado | B10: =FEVEREIRO26!H455 -> 29 | E10: 4 | F10: 4 | G10: =E10-F10 -> 0 | H10: =B10-C10+D10-G10 -> 29 | I10: =G10*6 -> 0
A11: Cupuaçu | B11: =FEVEREIRO26!H456 -> 27 | E11: 4 | F11: 4 | G11: =E11-F11 -> 0 | H11: =B11-C11+D11-G11 -> 27 | I11: =G11*6 -> 0
A12: Maracujá | B12: =FEVEREIRO26!H457 -> 9 | E12: 4 | F12: 3 | G12: =E12-F12 -> 1 | H12: =B12-C12+D12-G12 -> 8 | I12: =G12*6 -> 6
A13: Maracujá com nutella | B13: =FEVEREIRO26!H458 -> 15 | E13: 4 | F13: 4 | G13: =E13-F13 -> 0 | H13: =B13-C13+D13-G13 -> 15 | I13: =G13*6 -> 0
A14: Milho verde | B14: =FEVEREIRO26!H459 -> 10 | E14: 2 | F14: 1 | G14: =E14-F14 -> 1 | H14: =B14-C14+D14-G14 -> 9 | I14: =G14*6 -> 6
A15: Morango | B15: =FEVEREIRO26!H460 -> 8 | E15: 4 | F15: 3 | G15: =E15-F15 -> 1 | H15: =B15-C15+D15-G15 -> 7 | I15: =G15*6 -> 6
A16: Morango com Nutella | B16: =FEVEREIRO26!H461 -> 35 | E16: 6 | F16: 4 | G16: =E16-F16 -> 2 | H16: =B16-C16+D16-G16 -> 33 | I16: =G16*6 -> 12
A17: Mousse de limão | B17: =FEVEREIRO26!H462 -> 24 | E17: 4 | F17: 4 | G17: =E17-F17 -> 0 | H17: =B17-C17+D17-G17 -> 24 | I17: =G17*6 -> 0
A18: Ninho com Nutella | B18: =FEVEREIRO26!H463 -> 27 | E18: 8 | F18: 3 | G18: =E18-F18 -> 5 | H18: =B18-C18+D18-G18 -> 22 | I18: =G18*6 -> 30
... A24: Zero lactose morango | B24: =FEVEREIRO26!H469 -> 7 | E24: 2 | F24: 2 | G24: =E24-F24 -> 0 | H24: =B24-C24+D24-G24 -> 7 | I24: =G24*6 -> 0
A25: TOTAL | B25: =SUM(B3:B24) -> 505 | E25: =SUM(E2:E24) -> 100 | F25: =SUM(F2:F24) -> 84 | G25: =SUM(G2:G24) -> 16 | H25: =SUM(H3:H24) -> 488 | I25: =SUM(I2:I24) -> 96
F26: Saldo
B28: Data: 03/03/2026
A29: SABORES | B29: Estoque Inicial | C29: Furou | D29: Fez | E29: Quantidade de Geladinhos | F29: Voltaram | G29: Vendidos | H29: Estoque Final | I29: R$
A30: Abacate | B30: =H3 -> 19 | E30: 6 | F30: 4 | G30: =E30-F30 -> 2 | H30: =B30-C30+D30-G30 -> 17 | I30: =G30*6 -> 12
A31: Abacaxi | B31: =H4 -> 41 | E31: 4 | F31: 4 | G31: =E31-F31 -> 0 | H31: =B31-C31+D31-G31 -> 41 | I31: =G31*6 -> 0
A32: Açaí | B32: =H5 -> 40 | E32: 4 | F32: 2 | G32: =E32-F32 -> 2 | H32: =B32-C32+D32-G32 -> 38 | I32: =G32*6 -> 12
A33: Amendoim | B33: =H6 -> 29 | E33: 6 | F33: 6 | G33: =E33-F33 -> 0 | H33: =B33-C33+D33-G33 -> 29 | I33: =G33*6 -> 0
A34: Brigadeiro | B34: =H7 -> 26 | E34: 4 | F34: 2 | G34: =E34-F34 -> 2 | H34: =B34-C34+D34-G34 -> 24 | I34: =G34*6 -> 12
A35: Buriti | B35: =H8 -> 13 | E35: 4 | F35: 3 | G35: =E35-F35 -> 1 | H35: =B35-C35+D35-G35 -> 12 | I35: =G35*6 -> 6
A36: Coco | B36: =H9 -> 25 | E36: 4 | F36: 3 | G36: =E36-F36 -> 1 | H36: =B36-C36+D36-G36 -> 24 | I36: =G36*6 -> 6
A37: Coco Queimado | B37: =H10 -> 29 | E37: 4 | F37: 3 | G37: =E37-F37 -> 1 | H37: =B37-C37+D37-G37 -> 28 | I37: =G37*6 -> 6
A38: Cupuaçu | B38: =H11 -> 27 | E38: 4 | F38: 2 | G38: =E38-F38 -> 2 | H38: =B38-C38+D38-G38 -> 25 | I38: =G38*6 -> 12
A39: Maracujá | B39: =H12 -> 8 | E39: 4 | F39: 4 | G39: =E39-F39 -> 0 | H39: =B39-C39+D39-G39 -> 8 | I39: =G39*6 -> 0
A40: Maracujá com nutella | B40: =H13 -> 15 | E40: 4 | F40: 0 | G40: =E40-F40 -> 4 | H40: =B40-C40+D40-G40 -> 11 | I40: =G40*6 -> 24
A41: Milho verde | B41: =H14 -> 9 | E41: 2 | F41: 2 | G41: =E41-F41 -> 0 | H41: =B41-C41+D41-G41 -> 9 | I41: =G41*6 -> 0
A42: Morango | B42: =H15 -> 7 | D42: 30 | E42: 4 | F42: 3 | G42: =E42-F42 -> 1 | H42: =B42-C42+D42-G42 -> 36 | I42: =G42*6 -> 6
A43: Morango com Nutella | B43: =H16 -> 33 | E43: 6 | F43: 3 | G43: =E43-F43 -> 3 | H43: =B43-C43+D43-G43 -> 30 | I43: =G43*6 -> 18
A44: Mousse de limão | B44: =H17 -> 24 | E44: 4 | F44: 4 | G44: =E44-F44 -> 0 | H44: =B44-C44+D44-G44 -> 24 | I44: =G44*6 -> 0
A45: Ninho com Nutella | B45: =H18 -> 22 | E45: 8 | F45: 3 | G45: =E45-F45 -> 5 | H45: =B45-C45+D45-G45 -> 17 | I45: =G45*6 -> 30
A46: Ninho com Morango | B46: =H19 -> 17 | E46: 4 | F46: 1 | G46: =E46-F46 -> 3 | H46: =B46-C46+D46-G46 -> 14 | I46: =G46*6 -> 18
...

Sheet FEVEREIRO26
B1: Data: 02/02/2026
A2: SABORES | B2: Estoque Inicial | C2: Furou | D2: Fez | E2: Quantidade de Geladinhos | F2: Voltaram | G2: Vendidos | H2: Estoque Final | I2: R$
A3: Abacate | B3: 35 | E3: 6 | F3: 5 | G3: =E3-F3 -> 1 | H3: =B3-C3+D3-G3 -> 34 | I3: =G3*6 -> 6
A4: Abacaxi | B4: 12 | E4: 6 | F4: 4 | G4: =E4-F4 -> 2 | H4: =B4-C4+D4-G4 -> 10 | I4: =G4*6 -> 12
A5: Açaí | B5: 37 | E5: 6 | F5: 6 | G5: =E5-F5 -> 0 | H5: =B5-C5+D5-G5 -> 37 | I5: =G5*6 -> 0
A6: Amendoim | B6: 23 | C6: 6 | E6: 7 | F6: 5 | G6: =E6-F6 -> 2 | H6: =B6-C6+D6-G6 -> 15 | I6: =G6*6 -> 12
A7: Brigadeiro | B7: 25 | E7: 4 | F7: 3 | G7: =E7-F7 -> 1 | H7: =B7-C7+D7-G7 -> 24 | I7: =G7*6 -> 6
A8: Buriti | B8: 40 | E8: 8 | F8: 5 | G8: =E8-F8 -> 3 | H8: =B8-C8+D8-G8 -> 37 | I8: =G8*6 -> 18 | L8: =SUM(I24+I51+I78+I106+I134+I162+I190+I218+I246+I274+I302+I330+I358+I386+I414+I442+I470) -> 3774
A9: Coco | B9: 33 | E9: 5 | F9: 4 | G9: =E9-F9 -> 1 | H9: =B9-C9+D9-G9 -> 32 | I9: =G9*6 -> 6
A10: Coco Queimado | B10: 22 | E10: 4 | F10: 2 | G10: =E10-F10 -> 2 | H10: =B10-C10+D10-G10 -> 20 | I10: =G10*6 -> 12
A11: Cupuaçu | B11: 13 | E11: 6 | F11: 6 | G11: =E11-F11 -> 0 | H11: =B11-C11+D11-G11 -> 13 | I11: =G11*6 -> 0
A12: Maracujá | B12: 32 | E12: 6 | F12: 6 | G12: =E12-F12 -> 0 | H12: =B12-C12+D12-G12 -> 32 | I12: =G12*6 -> 0
A13: Maracujá com nutella | B13: 20 | E13: 6 | F13: 6 | G13: =E13-F13 -> 0 | H13: =B13-C13+D13-G13 -> 20 | I13: =G13*6 -> 0
A14: Milho verde | B14: 14 | E14: 2 | F14: 2 | G14: =E14-F14 -> 0 | H14: =B14-C14+D14-G14 -> 14 | I14: =G14*6 -> 0
A15: Morango | B15: 29 | E15: 5 | F15: 4 | G15: =E15-F15 -> 1 | H15: =B15-C15+D15-G15 -> 28 | I15: =G15*6 -> 6
A16: Morango com Nutella | B16: 17 | E16: 6 | F16: 5 | G16: =E16-F16 -> 1 | H16: =B16-C16+D16-G16 -> 16 | I16: =G16*6 -> 6
A17: Mousse de limão | B17: 10 | E17: 4 | F17: 3 | G17: =E17-F17 -> 1 | H17: =B17-C17+D17-G17 -> 9 | I17: =G17*6 -> 6
A18: Ninho com Nutella | B18: 35 | E18: 10 | F18: 3 | G18: =E18-F18 -> 7 | H18: =B18-C18+D18-G18 -> 28 | I18: =G18*6 -> 42
A19: Ninho com Morango | B19: 19 | E19: 6 | F19: 3 | G19: =E19-F19 -> 3 | H19: =B19-C19+D19-G19 -> 16 | I19: =G19*6 -> 18
A20: Oreo | B20: 17 | E20: 4 | F20: 3 | G20: =E20-F20 -> 1 | H20: =B20-C20+D20-G20 -> 16 | I20: =G20*6 -> 6
... A23: Zero lactose | B23: 24 | E23: 4 | F23: 3 | G23: =E23-F23 -> 1 | H23: =B23-C23+D23-G23 -> 23 | I23: =G23*6 -> 6
A24: TOTAL | B24: =SUM(B3:B23) -> 512 | E24: =SUM(E2:E23) -> 115 | F24: =SUM(F2:F23) -> 87 | G24: =SUM(G2:G23) -> 28 | H24: =SUM(H3:H23) -> 478 | I24: =SUM(I2:I23) -> 168
F25: Saldo
E26: Valor Total de Venda do dia - GELADINHOS | I26: =SUM(I3:I23) -> 168
B28: Data: 03/02/2026
A29: SABORES | B29: Estoque Inicial | C29: Furou | D29: Fez | E29: Quantidade de Geladinhos | F29: Voltaram | G29: Vendidos | H29: Estoque Final | I29: R$
A30: Abacate | B30: =H3 -> 34 | E30: 6 | F30: 0 | G30: =E30-F30 -> 6 | H30: =B30-C30+D30-G30 -> 28 | I30: =G30*6 -> 36
A31: Abacaxi | B31: =H4 -> 10 | E31: 6 | F31: 5 | G31: =E31-F31 -> 1 | H31: =B31-C31+D31-G31 -> 9 | I31: =G31*6 -> 6
A32: Açaí | B32: =H5 -> 37 | E32: 6 | F32: 6 | G32: =E32-F32 -> 0 | H32: =B32-C32+D32-G32 -> 37 | I32: =G32*6 -> 0
A33: Amendoim | B33: =H6 -> 15 | E33: 6 | F33: 3 | G33: =E33-F33 -> 3 | H33: =B33-C33+D33-G33 -> 12 | I33: =G33*6 -> 18
A34: Brigadeiro | B34: =H7 -> 24 | E34: 4 | F34: 3 | G34: =E34-F34 -> 1 | H34: =B34-C34+D34-G34 -> 23 | I34: =G34*6 -> 6
A35: Buriti | B35: =H8 -> 37 | E35: 6 | F35: 4 | G35: =E35-F35 -> 2 | H35: =B35-C35+D35-G35 -> 35 | I35: =G35*6 -> 12
A36: Coco | B36: =H9 -> 32 | E36: 5 | F36: 3 | G36: =E36-F36 -> 2 | H36: =B36-C36+D36-G36 -> 30 | I36: =G36*6 -> 12
A37: Coco Queimado | B37: =H10 -> 20 | E37: 4 | F37: 1 | G37: =E37-F37 -> 3 | H37: =B37-C37+D37-G37 -> 17 | I37: =G37*6 -> 18
A38: Cupuaçu | B38: =H11 -> 13 | E38: 6 | F38: 4 | G38: =E38-F38 -> 2 | H38: =B38-C38+D38-G38 -> 11 | I38: =G38*6 -> 12 | L38: 31
A39: Maracujá | B39: =H12 -> 32 | E39: 6 | F39: 4 | G39: =E39-F39 -> 2 | H39: =B39-C39+D39-G39 -> 30 | I39: =G39*6 -> 12 | L39: 3131
A40: Maracujá com nutella | B40: =H13 -> 20 | E40: 6 | F40: 6 | G40: =E40-F40 -> 0 | H40: =B40-C40+D40-G40 -> 20 | I40: =G40*6 -> 0
A41: Milho verde | B41: =H14 -> 14 | E41: 2 | F41: 2 | G41: =E41-F41 -> 0 | H41: =B41-C41+D41-G41 -> 14 | I41: =G41*6 -> 0
A42: Morango | B42: =H15 -> 28 | E42: 5 | F42: 5 | G42: =E42-F42 -> 0 | H42: =B42-C42+D42-G42 -> 28 | I42: =G42*6 -> 0
A43: Morango com Nutella | B43: =H16 -> 16 | E43: 6 | F43: 2 | G43: =E43-F43 -> 4 | H43: =B43-C43+D43-G43 -> 12 | I43: =G43*6 -> 24
...

Sheet JANEIRO26
B1: Data: 05/01/2026
A2: SABORES | B2: Estoque Inicial | C2: Furou | D2: Fez | E2: Quantidade de Geladinhos | F2: Voltaram | G2: Vendidos | H2: Estoque Final | I2: R$
A3: Abacate | B3: 36 | E3: 6 | F3: 6 | G3: =E3-F3 -> 0 | H3: =B3-C3+D3-G3 -> 36 | I3: =G3*6 -> 0
A4: Abacaxi | B4: 23 | E4: 5 | F4: 3 | G4: =E4-F4 -> 2 | H4: =B4-C4+D4-G4 -> 21 | I4: =G4*6 -> 12
A5: Açaí | B5: 16 | E5: 6 | F5: 6 | G5: =E5-F5 -> 0 | H5: =B5-C5+D5-G5 -> 16 | I5: =G5*6 -> 0
A6: Amendoim | B6: 24 | E6: 7 | F6: 6 | G6: =E6-F6 -> 1 | H6: =B6-C6+D6-G6 -> 23 | I6: =G6*6 -> 6
A7: Brigadeiro | B7: 25 | E7: 4 | F7: 3 | G7: =E7-F7 -> 1 | H7: =B7-C7+D7-G7 -> 24 | I7: =G7*6 -> 6
A8: Buriti | B8: 1 | D8: 34 | E8: 8 | F8: 5 | G8: =E8-F8 -> 3 | H8: =B8-C8+D8-G8 -> 32 | I8: =G8*6 -> 18
A9: Coco | B9: 32 | E9: 5 | F9: 5 | G9: =E9-F9 -> 0 | H9: =B9-C9+D9-G9 -> 32 | I9: =G9*6 -> 0
A10: Coco Queimado | B10: 14 | E10: 4 | F10: 4 | G10: =E10-F10 -> 0 | H10: =B10-C10+D10-G10 -> 14 | I10: =G10*6 -> 0
A11: Cupuaçu | B11: 6 | D11: 30 | E11: 5 | F11: 4 | G11: =E11-F11 -> 1 | H11: =B11-C11+D11-G11 -> 35 | I11: =G11*6 -> 6
A12: Maracujá | B12: 34 | E12: 6 | F12: 5 | G12: =E12-F12 -> 1 | H12: =B12-C12+D12-G12 -> 33 | I12: =G12*6 -> 6
A13: Maracujá com nutella | B13: 29 | E13: 6 | F13: 2 | G13: =E13-F13 -> 4 | H13: =B13-C13+D13-G13 -> 25 | I13: =G14*6 -> 0
A14: Milho verde | B14: 14 | D14: 4 | E14: 2 | F14: 2 | G14: =E14-F14 -> 0 | H14: =B14-C14+D14-G14 -> 18 | I14: =G15*6 -> 0
A15: Morango | B15: 28 | E15: 6 | F15: 6 | G15: =E15-F15 -> 0 | H15: =B15-C15+D15-G15 -> 28 | I15: =G15*6 -> 0
A16: Morango com Nutella | B16: 21 | E16: 6 | F16: 3 | G16: =E16-F16 -> 3 | H16: =B16-C16+D16-G16 -> 18 | I16: =G16*6 -> 18
A17: Mousse de limão | B17: 2 | C17: 1 | D17: 26 | E17: 4 | F17: 4 | G17: =E17-F17 -> 0 | H17: =B17-C17+D17-G17 -> 27 | I17: =G17*6 -> 0
A18: Ninho com Nutella | B18: 20 | E18: 8 | F18: 7 | G18: =E18-F18 -> 1 | H18: =B18-C18+D18-G18 -> 19 | I18: =G18*6 -> 6
A19: Ninho com Morango | B19: 28 | E19: 6 | F19: 5 | G19: =E19-F19 -> 1 | H19: =B19-C19+D19-G19 -> 27 | I19: =G19*6 -> 6
A20: Oreo | B20: 10 | E20: 4 | F20: 4 | G20: =E20-F20 -> 0 | H20: =B20-C20+D20-G20 -> 10 | I20: =G20*6 -> 0
A21: Prestígio | B21: 15 | E21: 8 | F21: 4 | G21: =E21-F21 -> 4 | H21: =B21-C21+D21-G21 -> 11 | I21: =G21*6 -> 24
A22: Uva | B22: 27 | E22: 2 | F22: 2 | G22: =E22-F22 -> 0 | H22: =B22-C22+D22-G22 -> 27 | I22: =G22*6 -> 0
A23: Zero lactose | B23: 14 | D23: 21 | E23: 6 | F23: 6 | G23: =E23-F23 -> 0 | H23: =B23-C23+D23-G23 -> 35 | I23: =G23*6 -> 0
A24: TOTAL | B24: =SUM(B3:B23) -> 419 | E24: =SUM(E2:E23) -> 114 | F24: =SUM(F2:F23) -> 92 | G24: =SUM(G2:G23) -> 22 | H24: =SUM(H3:H23) -> 511 | I24: =SUM(I2:I23) -> 108
F25: Saldo
E26: Valor Total de Venda do dia - GELADINHOS | I26: =SUM(I3:I23) -> 108
B28: Data: 06/01/2026
A29: SABORES | B29: Estoque Inicial | C29: Furou | D29: Fez | E29: Quantidade de Geladinhos | F29: Voltaram | G29: Vendidos | H29: Estoque Final | I29: R$
A30: Abacate | B30: =H3 -> 36 | E30: 6 | F30: 5 | G30: =E30-F30 -> 1 | H30: =B30-C30+D30-G30 -> 35 | I30: =G30*6 -> 6
A31: Abacaxi | B31: =H4 -> 21 | E31: 5 | F31: 3 | G31: =E31-F31 -> 2 | H31: =B31-C31+D31-G31 -> 19 | I31: =G31*6 -> 12
A32: Açaí | B32: =H5 -> 16 | E32: 5 | F32: 5 | G32: =E32-F32 -> 0 | H32: =B32-C32+D32-G32 -> 16 | I32: =G32*6 -> 0
A33: Amendoim | B33: =H6 -> 23 | E33: 6 | F33: 0 | G33: =E33-F33 -> 6 | H33: =B33-C33+D33-G33 -> 17 | I33: =G33*6 -> 36
A34: Brigadeiro | B34: =H7 -> 24 | E34: 4 | F34: 4 | G34: =E34-F34 -> 0 | H34: =B34-C34+D34-G34 -> 24 | I34: =G34*6 -> 0
A35: Buriti | B35: =H8 -> 32 | E35: 6 | F35: 5 | G35: =E35-F35 -> 1 | H35: =B35-C35+D35-G35 -> 31 | I35: =G35*6 -> 6
A36: Coco | B36: =H9 -> 32 | E36: 5 | F36: 5 | G36: =E36-F36 -> 0 | H36: =B36-C36+D36-G36 -> 32 | I36: =G36*6 -> 0
A37: Coco Queimado | B37: =H10 -> 14 | E37: 4 | F37: 3 | G37: =E37-F37 -> 1 | H37: =B37-C37+D37-G37 -> 13 | I37: =G37*6 -> 6
A38: Cupuaçu | B38: =H11 -> 35 | E38: 6 | F38: 6 | G38: =E38-F38 -> 0 | H38: =B38-C38+D38-G38 -> 35 | I38: =G38*6 -> 0
A39: Maracujá | B39: =H12 -> 33 | E39: 6 | F39: 5 | G39: =E39-F39 -> 1 | H39: =B39-C39+D39-G39 -> 32 | I39: =G39*6 -> 6
A40: Maracujá com nutella | B40: =H13 -> 25 | E40: 6 | F40: 3 | G40: =E40-F40 -> 3 | H40: =B40-C40+D40-G40 -> 22 | I40: =G41*6 -> 0
A41: Milho verde | B41: =H14 -> 18 | E41: 2 | F41: 2 | G41: =E41-F41 -> 0 | H41: =B41-C41+D41-G41 -> 18 | I41: =G42*6 -> 6
...

Sheet CONTROLE DE GASTOS
A1: Controle de gastos
A3: Cupuaçu
A4: Ingredientes | B4: Valor produto | C4: Volume | D4: Valor Unit. | E4: Quantidade | G4: UN | H4: Valor
A5: Açúcar | B5: 8 | C5: 2000 | D5: =B5/C5 -> 0.004 | E5: 400 | G5: G | H5: =D5*E5 -> 1.6
A6: Creme de leite | B6: 3 | C6: 1 | D6: =B6/C6 -> 3 | E6: 1 | G6: CX | H6: =D6*E6 -> 3
A7: Embalagem | B7: 35 | C7: 1000 | D7: =B7/C7 -> 0.035 | E7: 20 | G7: un | H7: =D7*E7 -> 0.7
A8: Etiqueta | B8: 120 | C8: 1000 | D8: =B8/C8 -> 0.12 | E8: 20 | G8: UN | H8: =D8*E8 -> 2.4 | J8: Gasto Produção | K8: Geladinho Produzido | L8: Valor Venda | M8: Valor Bruto | N8: Lucro
A9: Leite condensado | B9: 4.5 | C9: 1 | D9: =B9/C9 -> 4.5 | E9: 1 | G9: CX | H9: =D9*E9 -> 4.5 | J9: =H14 -> 30.12 | K9: 20 | L9: 6 | M9: =K9*L9 -> 120 | N9: =M9-J9 -> 89.88
A10: Leite em pó | B10: 38 | C10: 1000 | D10: =B10/C10 -> 0.038 | E10: 60 | G10: G | H10: =D10*E10 -> 2.28
A11: Leite integral | B11: 5 | C11: 1 | D11: =B11/C11 -> 5 | E11: 1.5 | G11: L | H11: =D11*E11 -> 7.5
A12: Liga neutra | B12: 32 | C12: 1000 | D12: =B12/C12 -> 0.032 | E12: 20 | G12: G | H12: =D12*E12 -> 0.64
A13: Polpa | B13: 25 | C13: 1000 | D13: =B13/C13 -> 0.025 | E13: 300 | G13: pc | H13: =D13*E13 -> 7.5
E14: Total | H14: =SUM(H5:H13) -> 30.12
A15: Controle de gastos
A17: Açaí
A18: Açúcar | B18: 8 | C18: 2000 | D18: =B18/C18 -> 0.004 | E18: 500 | G18: G | H18: =D18*E18 -> 2
A19: Creme de leite | B19: 3 | C19: 1 | D19: =B19/C19 -> 3 | E19: 1 | G19: CX | H19: =D19*E19 -> 3
A20: Banana | B20: 6 | C20: 1000 | D20: =B20/C20 -> 0.006 | E20: 96 | G20: g | H20: =D20*E20 -> 0.576
A21: Base - açaí | B21: 40 | C21: 1000 | D21: =B21/C21 -> 0.04 | E21: 75 | G21: g | H21: =D21*E21 -> 3
A22: Embalagem | B22: 35 | C22: 1000 | D22: =B22/C22 -> 0.035 | E22: 30 | G22: un | H22: =D22*E22 -> 1.05
A23: Etiqueta | B23: 120 | C23: 1000 | D23: =B23/C23 -> 0.12 | E23: 30 | G23: UN | H23: =D23*E23 -> 3.6 | J23: Gasto Produção | K23: Geladinho Produzido | L23: Valor Venda | M23: Valor Bruto | N23: Lucro
A24: Leite condensado triângulo | B24: 4.5 | C24: 1 | D24: =B24/C24 -> 4.5 | E24: 2 | G24: CX | H24: =D24*E24 -> 9 | J24: =H29 -> 62.486 | K24: 30 | L24: 6 | M24: =K24*L24 -> 180 | N24: =M24-J24 -> 117.514
A25: Leite em pó | B25: 38 | C25: 1000 | D25: =B25/C25 -> 0.038 | E25: 60 | G25: G | H25: =D25*E25 -> 2.28
A26: Leite integral | B26: 5 | C26: 1 | D26: =B26/C26 -> 5 | E26: 1.5 | G26: L | H26: =D26*E26 -> 7.5
A27: Liga neutra | B27: 32 | C27: 1000 | D27: =B27/C27 -> 0.032 | E27: 15 | G27: G | H27: =D27*E27 -> 0.48
A28: Polpa | B28: 30 | C28: 1000 | D28: =B28/C28 -> 0.03 | E28: 1000 | G28: pc | H28: =D28*E28 -> 30
E29: Total | H29: =SUM(H18:H28) -> 62.486
A31: Controle de gastos
A33: Coco/Coco queimado
A34: Ingredientes | B34: Valor produto | C34: Volume | D34: Valor Unit. | E34: Quantidade | H34: Valor
A35: Açúcar | B35: 8 | C35: 2000 | D35: =B35/C35 -> 0.004 | E35: 450 | G35: G | H35: =D35*E35 -> 1.8
A36: Coco Ralado seco | B36: 45 | C36: 1000 | D36: =B36/C36 -> 0.045 | E36: 100 | G36: G | H36: =D36*E36 -> 4.5
A37: Coco Ralado fresco | B37: 20 | C37: 1000 | D37: =B37/C37 -> 0.02 | E37: 100 | G37: G | H37: =D37*E37 -> 2
A38: Creme de leite | B38: 3 | C38: 1 | D38: =B38/C38 -> 3 | E38: 1 | G38: CX | H38: =D38*E38 -> 3 | J38: Gasto Produção | K38: Geladinho Produzido | L38: Valor Venda | M38: Valor Bruto | N38: Lucro
A39: Embalagem | B39: 35 | C39: 1000 | D39: =B39/C39 -> 0.035 | E39: 25 | G39: un | H39: =D39*E39 -> 0.875
A40: Etiqueta | B40: 120 | C40: 1000 | D40: =B40/C40 -> 0.12 | E40: 25 | G40: UN | H40: =D40*E40 -> 3 | J40: =H46 -> 33.095 | K40: 25 | L40: 6 | M40: 125 | N40: 89.69
A41: Leite condensado | B41: 4.5 | C41: 1 | D41: =B41/C41 -> 4.5 | E41: 1 | G41: CX | H41: =D41*E41 -> 4.5
A42: Leite de coco | B42: 3 | C42: 1 | D42: =B42/C42 -> 3 | E42: 1 | G42: VD | H42: =D42*E42 -> 3
A43: Leite em pó | B43: 38 | C43: 1000 | D43: =B43/C43 -> 0.038 | E43: 60 | G43: G | H43: =D43*E43 -> 2.28
A44: Leite integral | B44: 5 | C44: 1 | D44: =B44/C44 -> 5 | E44: 1.5 | G44: LT | H44: =D44*E44 -> 7.5
...
